6. **例外処理**

**例外の基礎 (`try-catch-finally`)**

例外処理は、プログラムの実行中に発生するエラー（例外）を適切に処理するための機能です。`try-catch-finally`ブロックを使用して例外を捕捉し、エラーに対処します。

```java
public class ExceptionExample {
    public static void main(String[] args) {
        try {
            int result = divide(10, 0); // 0で割り算を試みる
            System.out.println("結果: " + result);
        } catch (ArithmeticException e) {
            System.out.println("エラーが発生しました: " + e.getMessage());
        } finally {
            System.out.println("処理が終了しました。");
        }
    }

    public static int divide(int a, int b) {
        return a / b;
    }
}
```

**出力:**

```
エラーが発生しました: / by zero
処理が終了しました。
```

- `try`ブロック内には、例外が発生する可能性のあるコードを記述します。
- `catch`ブロックでは、特定の例外を捕捉し、その処理を行います。
- `finally`ブロックは、例外の発生有無にかかわらず必ず実行され、リソースの解放などに使用します。

**例外の種類 (`Exception`と`Error`)**

Javaの例外は主に以下の2つに分類されます。

1. **`Exception`クラス**

   - プログラムが適切に処理できる例外。
   - チェックされる例外（例: `IOException`）とチェックされない例外（例: `NullPointerException`）があります。

2. **`Error`クラス**

   - プログラムが回復不能な重大なエラー。
   - 例: `OutOfMemoryError`, `StackOverflowError`

```java
public class ExceptionTypesExample {
    public static void main(String[] args) {
        // チェックされない例外の例
        try {
            String text = null;
            System.out.println(text.length()); // NullPointerExceptionが発生
        } catch (NullPointerException e) {
            System.out.println("NullPointerExceptionをキャッチしました。");
        }

        // エラーの例
        try {
            causeError(); // StackOverflowErrorを発生させる
        } catch (StackOverflowError e) {
            System.out.println("StackOverflowErrorをキャッチしました。");
        }
    }

    public static void causeError() {
        causeError(); // 無限再帰
    }
}
```

**カスタム例外の作成**

独自の例外クラスを作成することで、特定の状況に対する詳細なエラー処理が可能になります。カスタム例外は`Exception`クラスを継承して作成します。

```java
// カスタム例外クラス
public class InsufficientFundsException extends Exception {
    public InsufficientFundsException(String message) {
        super(message);
    }
}

// カスタム例外の使用例
public class BankAccount {
    private double balance;

    public BankAccount(double balance) {
        this.balance = balance;
    }

    public void withdraw(double amount) throws InsufficientFundsException {
        if (balance < amount) {
            throw new InsufficientFundsException("残高不足です。引き出し額: " + amount + ", 残高: " + balance);
        }
        balance -= amount;
    }

    public double getBalance() {
        return balance;
    }
}

// メインクラス
public class CustomExceptionExample {
    public static void main(String[] args) {
        BankAccount account = new BankAccount(10000);

        try {
            account.withdraw(15000);
        } catch (InsufficientFundsException e) {
            System.out.println("エラー: " + e.getMessage());
        }
    }
}
```

**出力:**

```
エラー: 残高不足です。引き出し額: 15000.0, 残高: 10000.0
```

**`throws`と例外の伝播**

メソッドが例外をスローする可能性がある場合、`throws`キーワードを使用して例外を宣言します。これにより、例外を呼び出し元に伝播させることができます。

```java
import java.io.BufferedReader;
import java.io.FileReader;
import java.io.IOException;

public class ThrowsExample {
    public static void main(String[] args) {
        try {
            readFile("sample.txt");
        } catch (IOException e) {
            System.out.println("ファイル読み込みエラー: " + e.getMessage());
        }
    }

    // 例外をスローするメソッド
    public static void readFile(String fileName) throws IOException {
        BufferedReader reader = new BufferedReader(new FileReader(fileName));
        String line = reader.readLine();
        System.out.println("ファイルの内容: " + line);
        reader.close();
    }
}
```

- `readFile`メソッドは`IOException`をスローする可能性があるため、`throws IOException`を宣言しています。
- 呼び出し元の`main`メソッドでは、`try-catch`ブロックで例外を処理しています。

**まとめ**

- `try-catch-finally`ブロックを使用して、例外を適切に処理します。
- 例外は`Exception`（回復可能）と`Error`（回復不能）に大別されます。
- カスタム例外を作成することで、より詳細なエラー処理が可能になります。
- `throws`キーワードを使用して、例外を呼び出し元に伝播させることができます。

適切な例外処理を行うことで、予期しないエラーによるプログラムのクラッシュを防ぎ、ユーザーにとって信頼性の高いアプリケーションを提供できます。